<?xml version="1.0"?>
<robot name="simple_drone">
    <!-- Основной корпус -->
    <link name="base_link">
        <visual>
            <geometry>
                <cylinder radius="0.2" length="0.1"/>
            </geometry>
            <material name="blue">
                <color rgba="0 0 1 1"/>
            </material>
        </visual>
        <collision>
            <geometry>
                <cylinder radius="0.2" length="0.1"/>
            </geometry>
        </collision>
        <inertial>
            <mass value="1.0"/>
            <inertia ixx="0.01" ixy="0" ixz="0" iyy="0.01" iyz="0" izz="0.01"/>
        </inertial>
    </link>

    <!-- Мотор 1 -->
    <joint name="motor1" type="revolute">
        <parent link="base_link"/>
        <child link="motor1_link"/>
        <origin xyz="0.2 0.2 0.1" rpy="0 0 0"/>
        <axis xyz="0 0 1"/>
        <limit effort="10" velocity="10"/>
    </joint>
    <link name="motor1_link">
        <visual>
            <geometry>
                <cylinder radius="0.05" length="0.05"/>
            </geometry>
        </visual>
        <collision>
            <geometry>
                <cylinder radius="0.05" length="0.05"/>
            </geometry>
        </collision>
        <inertial>
            <mass value="0.1"/>
            <inertia ixx="0.001" ixy="0" ixz="0" iyy="0.001" iyz="0" izz="0.001"/>
        </inertial>
    </link>

    <!-- Мотор 2 -->
    <joint name="motor2" type="revolute">
        <parent link="base_link"/>
        <child link="motor2_link"/>
        <origin xyz="0.2 -0.2 0.1" rpy="0 0 0"/>
        <axis xyz="0 0 1"/>
        <limit effort="10" velocity="10"/>
    </joint>
    <link name="motor2_link">
        <visual>
            <geometry>
                <cylinder radius="0.05" length="0.05"/>
            </geometry>
        </visual>
        <collision>
            <geometry>
                <cylinder radius="0.05" length="0.05"/>
            </geometry>
        </collision>
        <inertial>
            <mass value="0.1"/>
            <inertia ixx="0.001" ixy="0" ixz="0" iyy="0.001" iyz="0" izz="0.001"/>
        </inertial>
    </link>

    <!-- Мотор 3 -->
    <joint name="motor3" type="revolute">
        <parent link="base_link"/>
        <child link="motor3_link"/>
        <origin xyz="-0.2 0.2 0.1" rpy="0 0 0"/>
        <axis xyz="0 0 1"/>
        <limit effort="10" velocity="10"/>
    </joint>
    <link name="motor3_link">
        <visual>
            <geometry>
                <cylinder radius="0.05" length="0.05"/>
            </geometry>
        </visual>
        <collision>
            <geometry>
                <cylinder radius="0.05" length="0.05"/>
            </geometry>
        </collision>
        <inertial>
            <mass value="0.1"/>
            <inertia ixx="0.001" ixy="0" ixz="0" iyy="0.001" iyz="0" izz="0.001"/>
        </inertial>
    </link>

    <!-- Мотор 4 -->
    <joint name="motor4" type="revolute">
        <parent link="base_link"/>
        <child link="motor4_link"/>
        <origin xyz="-0.2 -0.2 0.1" rpy="0 0 0"/>
        <axis xyz="0 0 1"/>
        <limit effort="10" velocity="10"/>
    </joint>
    <link name="motor4_link">
        <visual>
            <geometry>
                <cylinder radius="0.05" length="0.05"/>
            </geometry>
        </visual>
        <collision>
            <geometry>
                <cylinder radius="0.05" length="0.05"/>
            </geometry>
        </collision>
        <inertial>
            <mass value="0.1"/>
            <inertia ixx="0.001" ixy="0" ixz="0" iyy="0.001" iyz="0" izz="0.001"/>
        </inertial>
    </link>
</robot>